Workbook
Name Climate: Settings!$C$10
Name Country: Settings!$C$7
Name Development_status: Settings!$C$9
Name Region: Settings!$C$8
Name Year: Settings!$C$6
Name Year1: Settings!$C$13
Name Year2: Settings!$C$14
Name Year3: Settings!$C$15

Sheet Intro
B1: ="This workbook contains the baseline of the "&B17&" sectors energy flow" -> This workbook contains the baseline of the Afolu sectors energy flow
B4: Color coding:
C5: TIMES input files, imports data from blue sheets only
C6: Calculation sheets, used for calculating values, such as stocks, full load hours, etc. based on raw input data and default values.
C7: Default values either country specific values or international average values.
C8: Input of raw data from the statistics
C10: Cells containing parameter values
B13: Model specific information
B16: 2022 | C16: insert base modelling year
B17: Afolu | C17: Insert main sector name
B18: AFO | C18: insert short sector name
B20: Total overview of regions within the model
B21: Region number | C21: 1 | D21: 2 | E21: 3 | F21: 4 | G21: 5 | H21: 6 | I21: 7 | J21: 8 | K21: 9 | L21: 10 | M21: 11 | N21: 12 | O21: 13 | P21: 14 | Q21: 15 | R21: 16 | S21: 17 | T21: 18 | U21: 19 | V21: 20 | W21: 21 | X21: 22 | Y21: 23 | Z21: 24 | AA21: 25 | AB21: 26 | AC21: 27 | AD21: 28 | AE21: 29 | AF21: 30
B22: Region name | C22: REG1
B25: Calibration to match existing national Emission Inventory
B27: Total AFOLU sectors emissions | G27: Emission inventory values | L27: Calibration factor
E28: 2019 | J28: =$B$16 -> 2022 | O28: =$B$16 -> 2022
B29: CH4 | G29: CH4 | L29: CH4 | O29: 1
B30: N2O | G30: N2O | L30: N2O | O30: 1
B31: CO2 | G31: CO2 | L31: CO2 | O31: 1
B32: CO2sinks (negative from e.g. Forest) | G32: CO2sinks (negative from e.g. Forrest) | L32: CO2sinks (negative from e.g. Forrest) | O32: 1
B53: Illustration of residential sectors energy flow
B72: Trademark/Legal stuff

Sheet Settings
B1: Settings
Q4: Conversion factors
C5: Select: | G5: Country list | I5: Region types | K5: Development status | M5: Climate type
B6: Year | C6: 2022 | G6: Afghanistan | I6: North America | K6: Developing country | M6: Temperate | Q6: 1000000000 | R6: liters/Mm3
B7: Country | C7: Sweden | G7: Albania | I7: Western Europe | K7: Developed country | M7: Warm | Q7: 0.0001 | R7: ton/hg
B8: Region | C8: Europe | G8: Algeria | I8: Eastern Europe | M8: Cool | Q8: =10^(-3) -> 0.001 | R8: TJ/GJ
B9: Development | C9: Developed country | G9: American Samoa | I9: Oceania
B10: Climate | C10: Cool | G10: Andorra | I10: Latin America
G11: Angola | I11: Africa
G12: Anguilla | I12: Middle East
G13: Antigua and Barbuda | I13: Asia
G14: Argentina
G15: Armenia
G16: Aruba
G17: Australia
G18: Austria
G19: Azerbaijan
G20: Bahamas
G21: Bahrain
G22: Bangladesh
G23: Barbados
G24: Belarus
G25: Belgium
... G244: Zimbabwe

Sheet Lookup tables
A1: Lookup tables
A3: Crop name (FAO database) | B3: IPCC Category | D3: Crop name (FAO crop calendar) | E3: IPCC Category | G3: Animal names (FAO) | H3: Animal names (FAOSTAT) | I3: Animal names (CH4 table EFDB IPCC) | J3: Animal names (N2O table EFDB IPCC) | L3: Cerial names | M3: Biomass names
A4: Barley | B4: Cereals | D4: Bananas | E4: Woody crops | G4: Asses | H4: Asses | I4: Mules and Asses | J4: Other animals | L4: Barley | M4: Barley straw
A5: Olives | B5: Woody crops | D5: Bananas | E5: Woody crops | G5: Camels | H5: Camels | I5: Camels | J5: Other animals | L5: Wheat | M5: Wheat straw
A6: Wheat | B6: Cereals | D6: Bananas and plantains | E6: Woody crops | G6: Cattle, dairy | H6: Cattle, dairy | I6: Dairy cows | J6: Dairy cattle | L6: Oats | M6: Oat straw
A7: Grapes | B7: Woody crops | D7: Bananas˚ | E7: Woody crops | G7: Cattle, non-dairy | H7: Cattle, non-dairy | I7: Other cattle | J7: Non-dairy cattle | L7: Maize (corn) | M7: Maize cob
A8: Almonds, in shell | B8: Woody crops | D8: Barley | E8: Cereals | G8: Goats | H8: Goats | I8: Goats | J8: Other animals | L8: Triticale | M8: Average
A9: Sunflower seed | B9: Seeds | D9: Barley | E9: Cereals | G9: Horses | H9: Horses | I9: Horses | J9: Other animals | L9: Rye | M9: Rye straw
A10: Oats | B10: Cereals | D10: Barley and other cereals | E10: Cereals | G10: Mules and hinnies | H10: Mules and hinnies | I10: Mules and Asses | J10: Other animals | L10: Mixed grain | M10: Average
A11: Maize (corn) | B11: Cereals | D11: Barley and other cereals | E11: Cereals | G11: Sheep | H11: Sheep | I11: Sheep | J11: Sheep | L11: Cereals n.e.c. | M11: Average
A12: Triticale | B12: Cereals | D12: Barley and wheat | E12: Cereals | G12: Buffalo | H12: Buffalo | I12: Buffalo | J12: Other animals | L12: Sorghum | M12: Sorghum straw/stalk
A13: Other pulses n.e.c. | B13: Legumes | D13: Barley spring | E13: Cereals | G13: Swine, breeding | H13: Swine, breeding | I13: Swine | J13: Swine | L13: Buckwheat | M13: Average
A14: Oranges | B14: Woody crops | D14: Barley winter | E14: Cereals | G14: Swine, market | H14: Swine, market | I14: Swine | J14: Swine | L14: Fonio | M14: Average
... A18: Rice | B18: Rice | D18: Cereals 1 | E18: Cereals | G18: Poultry | H18: Poultries | I18: Ducks | J18: Ducks | L18: Rice | M18: Rice straw
A19: Peaches and nectarines | B19: Woody crops | D19: Cereals 2 | E19: Cereals | G19: Poultry | H19: Ducks | I19: Turkeys | J19: Turkeys
A20: Rape or colza seed | B20: Seeds | D20: Citrus | E20: Woody crops | G20: Poultry | H20: Turkeys
A21: Potatoes | B21: Roots | D21: Citrus | E21: Woody crops
A22: Tomatoes | B22: Vegetables | D22: Citrus ˚ | E22: Woody crops
A23: Other nuts (excluding wild edible nuts and groundnuts), in shell, n.e.c. | B23: Woody crops | D23: Citrus˚ | E23: Woody crops
A24: Lemons and limes | B24: Woody crops | D24: Cocoa | E24: Woody crops
A25: Mixed grain | B25: Cereals | D25: Coconut | E25: Woody crops
A26: Cauliflowers and broccoli | B26: Vegetables | D26: Coffee | E26: Woody crops
A27: Chestnuts, in shell | B27: Woody crops | D27: Coffee | E27: Woody crops
A28: Lettuce and chicory | B28: Herbs and greens | D28: Coffee˚ | E28: Woody crops
A29: Other tropical fruits, n.e.c. | B29: Woody crops | D29: Cotton | E29: Fiber crops
A30: Apples | B30: Woody crops | D30: Cotton | E30: Fiber crops
A31: Green garlic | B31: Vegetables | D31: Cotton˚ | E31: Fiber crops
A32: Cherries | B32: Woody crops | D32: Date palm | E32: Woody crops
... A161: Yautia | B161: Roots | D161: Sugar beets | E161: Roots
D162: Sugar beets˚ | E162: Roots
D163: Sugarcane | E163: Vegetables
D164: Sugarcane | E164: Vegetables
D165: Sugarcane˚ | E165: Vegetables
D166: Summer cereals | E166: Cereals
D167: Sunflower | E167: Seeds
D168: Sunflower | E168: Seeds
D169: Sunflower˚ | E169: Seeds
D170: Sunflowers | E170: Seeds
D171: Sweet potatoes | E171: Roots
D172: Sweet potatoes | E172: Roots
...

Sheet Fuel-Technology
A1: This sheet contains the commodities definitions for the AFOLU sector
B3: ~FI_Comm | H3: ~FI_Process | T3: ~FI_T
B4: CSet | C4: CommName | D4: CommDesc | E4: Unit | F4: LimType | H4: Sets | I4: TechName | J4: TechDesc | K4: Tact | L4: Tcap | M4: Tslvl | N4: Vintage | P4: TechName | Q4: *TechDesc | R4: Comm-IN | S4: Comm-OUT | T4: CAP2ACT | U4: EFF | V4: AFA | W4: LIFE
B5: \I: | C5: Name | D5: Description | E5: Activity | H5: \I: | I5: Name | J5: Description | K5: Activity | L5: Capacity | M5: Timeslice levels | N5: Tracking of investment year | P5: \I: Unit | S5: Kha | T5: KhaA/kha | U5: TJ/kha | V5: Annual aviability | W5: Years
B6: ENV | C6: AFOBGACH4 | D6: Biogas - CH4 reduction | E6: ktCH4 | H6: PRE | I6: MINWTR | J6: Mining Of Water | K6: Mm3 | L6: Mm3 | M6: Annual | N6: NO | P6: MINWTR | Q6: =J6 -> Mining Of Water | S6: WTRAFO | T6: 1 | U6: 1 | V6: 1 | W6: 100
B7: ENV | C7: AFOBGAN2O | D7: Biogas - N2O reduction | E7: ktN2O
B8: ENV | C8: AFOCRPCH4 | D8: Crop CH4 | E8: ktCH4
B9: ENV | C9: AFOCRPCO2 | D9: Crop CO2 | E9: ktCO2
B10: ENV | C10: AFOCRPN2O | D10: Crop N2O | E10: ktN2O
B11: ENV | C11: AFOFRSCO2 | D11: Forest CO2 | E11: ktCO2
B12: ENV | C12: AFOLIVCH4 | D12: Livestock - enteric fermentation | E12: ktCH4
B13: ENV | C13: AFOMNRCH4 | D13: Livestock - manure management CH4 | E13: ktCH4
B14: ENV | C14: AFOMNRN2O | D14: Livestock - manure management N2O | E14: ktN2O
B15: ENV | C15: AFOPASN2O | D15: Pasture N2O | E15: ktN2O
B16: ENV | C16: GHGAFO | D16: Total AFOLU GHG Emission | E16: kt CO2e
B17: ENV | C17: GHGAFOCH4 | D17: GHG Emissions Agriculture AFOLU CH4 Emissions kt CO2e | E17: kt CO2e
B18: ENV | C18: GHGAFOCO2 | D18: GHG Emissions Agriculture AFOLU CO2 Emissions kt CO2e | E18: kt CO2e
... B30: MAT | C30: AFOPASGEP | D30: Pasture land | E30: kha
B31: MAT | C31: CADMNR | D31: Cattle Dairy Manure | E31: ktCH4 | F31: FX
B32: MAT | C32: CADMNRNNN | D32: Cattle Dairy Manure No Treatment | E32: ktCH4 | F32: FX
B33: MAT | C33: CADMNRANN | D33: Cattle Dairy Manure Acidification | E33: ktCH4 | F33: FX
B34: MAT | C34: CADMNRNDN | D34: Cattle Dairy Manure Daily_Weekly_Manure_Removal | E34: ktCH4 | F34: FX
B35: MAT | C35: CADMNRNNM | D35: Cattle Dairy Manure Manure_Storage_Covers | E35: ktCH4 | F35: FX
B36: MAT | C36: CADMNRADN | D36: Cattle Dairy Manure Acidification + Daily_Weekly_Manure_Removal | E36: ktCH4 | F36: FX
B37: MAT | C37: CADMNRNDM | D37: Cattle Dairy Manure Acidification + Manure_Storage_Covers | E37: ktCH4 | F37: FX
B38: MAT | C38: CADMNRANM | D38: Cattle Dairy Manure Daily_Weekly_Manure_Removal + Manure_Storage_Covers | E38: ktCH4 | F38: FX
B39: MAT | C39: CADMNRADM | D39: Cattle Dairy Manure Acidification + Daily_Weekly_Manure_Removal + Manure_Storage_Covers | E39: ktCH4 | F39: FX
B40: MAT | C40: CANMNR | D40: Cattle Non Dairy Manure | E40: ktCH4 | F40: FX
B41: MAT | C41: CANMNRNNN | D41: Cattle Non Dairy Manure No Treatment | E41: ktCH4 | F41: FX
B42: MAT | C42: CANMNRANN | D42: Cattle Non Dairy Manure Acidification | E42: ktCH4 | F42: FX
... B48: MAT | C48: CANMNRADM | D48: Cattle Non Dairy Manure Acidification + Daily_Weekly_Manure_Removal + Manure_Storage_Covers | E48: ktCH4 | F48: FX
B49: MAT | C49: CERSTR | D49: Cereal straw | E49: Mton
B50: MAT | C50: FCRWSB | D50: Fiber crops straw | E50: Mton
B51: MAT | C51: FRSFIW | D51: Forest area with FIW | E51: kha
B52: MAT | C52: FRSNATGEF | D52: Naturally regenerating | E52: kha
B53: MAT | C53: FRSPLAGEF | D53: Planted | E53: kha
B54: MAT | C54: FRSWOC | D54: Forest area with WOC | E54: kha
B55: MAT | C55: FRSWOP | D55: Forest area with WOP | E55: kha
B56: MAT | C56: HAGWSB | D56: Herbs and greens straw | E56: Mton
B57: MAT | C57: LEGWSB | D57: Legumes straw | E57: Mton
...

Sheet Crops
A1: This sheet contains the Crop technologies
B5: ~FI_Process | K5: ~FI_T
B6: Sets | C6: TechName | D6: TechDesc | E6: Techtype long | F6: Option long | G6: Tact | H6: Tcap | I6: Tslvl | K6: TechName | L6: *TechDesc | M6: Comm-IN | N6: Comm-OUT | O6: Comm-OUT-A | P6: CAP2ACT | Q6: EFF | R6: AFA~FX | S6: LIFE | T6: START | U6: OUTPUT | V6: EMISSIONS~AFOCRPCO2 | W6: EMISSIONS~AFOCRPCH4 | X6: EMISSIONS~AFOCRPN2O | Y6: NCAP_PASTI | Z6: FIXOM | AA6: NCAP_COST
B7: * | C7: Name | D7: Description | G7: Activity | H7: Capacity | I7: Timeslice levels | K7: \I: Unit | M7: Mm3 | N7: Mton | O7: TJ | P7: Mton/kha | Q7: Mton/Mm3 | R7: Annual aviability | S7: Years | T7: Year | U7: Mton/Mton | V7: ktCO2/Mton | W7: ktCH4/Mton | X7: ktN2O/Mton | Y7: *kha | Z7: MEUR/kha | AA7: MEUR/kha
B8: =IF(Y8=0,"\I:","DMD") -> DMD | C8: AFOCRPOFICERWTRE0 | D8: Afolu Crops Open Field Cereals Existing 0 | E8: Open Field | F8: Cereals | G8: Mton | H8: kha | I8: Annual | K8: =IF(Y8="","\I:",C8) -> AFOCRPOFICERWTRE0 | L8: Afolu Crops Open Field Cereals Existing 0 | M8: WTRAFO | N8: AFOCRPCERDEM | P8: =IF(IFERROR(VLOOKUP($K8,'Calc - Crops'!$L$24:$Y$47,8,FALSE)," ")=0," ",IFERROR(VLOOKUP($K8,'Calc - Crops'!$L$24:$Y$47,8,FALSE)/1000," ")) -> 0.00061073654 | Q8: =IF(IFERROR(P8/(IFERROR(VLOOKUP(F8,'Calc - water'!$B$39:$G$48,6,FALSE),"")*IFERROR(VLOOKUP(E8,DefaultAFOLU!$C$32:$G$39,5,FALSE),"")),"")=0," ",IFERROR(P8/(IFERROR(VLOOKUP(F8,'Calc - water'!$B$39:$G$48,6,FALSE),"")*IFERROR(VLOOKUP(E8,DefaultAFOLU!$C$32:$G$39,5,FALSE),"")),"")) -> 6.1073654 | R8: 1 | S8: 4 | T8: =IF(Y8=0,Intro!$B$16+1,"") | V8: =IF(IFERROR(VLOOKUP($K8,'Calc - Crops'!$L$24:$Y$47,11,FALSE)," ")=0," ",IFERROR(VLOOKUP($K8,'Calc - Crops'!$L$24:$Y$47,11,FALSE)/$P8," ")) -> 13374.1 | W8: =IF(IFERROR(VLOOKUP($K8,'Calc - Crops'!$L$24:$Y$47,10,FALSE)," ")=0," ",IFERROR(VLOOKUP($K8,'Calc - Crops'!$L$24:$Y$47,10,FALSE)/$P8," ")) -> 0.68463386 | X8: =IF(IFERROR(VLOOKUP($K8,'Calc - Crops'!$L$24:$Y$47,9,FALSE)," ")=0," ",IFERROR(VLOOKUP($K8,'Calc - Crops'!$L$24:$Y$47,9,FALSE)/$P8," ")) -> 18.664672 | Y8: =IFERROR(VLOOKUP($C8,'Calc - Crops'!$L$24:$Y$47,2,FALSE)/1000, " ") -> 953.47 | Z8: =IF(E8<>"",SUMIFS('Input data - Other'!$F:$F,'Input data - Other'!$B:$B,Crops!Z$6,'Input data - Other'!$D:$D,Crops!$E8),"") -> 0.156 | AA8: =IF(F8<>"",SUMIFS('Input data - Other'!$F:$F,'Input data - Other'!$B:$B,Crops!AA$6,'Input data - Other'!$D:$D,Crops!$E8),"") -> 0
B9: \I: | K9: =IF(Y8="","\I:"," ") | O9: CERSTR | P9: =IF(IFERROR(VLOOKUP($K9,'Calc - Crops'!$L$24:$Y$47,8,FALSE)," ")=0," ",IFERROR(VLOOKUP($K9,'Calc - Crops'!$L$24:$Y$47,8,FALSE)/1000," ")) | Q9: =IF(IFERROR(P9/(IFERROR(VLOOKUP(F9,'Calc - water'!$B$39:$G$48,6,FALSE),"")*IFERROR(VLOOKUP(E9,DefaultAFOLU!$C$32:$G$39,5,FALSE),"")),"")=0," ",IFERROR(P9/(IFERROR(VLOOKUP(F9,'Calc - water'!$B$39:$G$48,6,FALSE),"")*IFERROR(VLOOKUP(E9,DefaultAFOLU!$C$32:$G$39,5,FALSE),"")),"")) | T9: =IF(Y9=0,Intro!$B$16+1,"") | U9: =IFERROR(VLOOKUP(O9,DefaultAFOLU!$D$42:$G$50,4,TRUE)," ") -> 0.3 | V9: =IF(IFERROR(VLOOKUP($K9,'Calc - Crops'!$L$24:$Y$47,11,FALSE)," ")=0," ",IFERROR(VLOOKUP($K9,'Calc - Crops'!$L$24:$Y$47,11,FALSE)/$P9," ")) | W9: =IF(IFERROR(VLOOKUP($K9,'Calc - Crops'!$L$24:$Y$47,10,FALSE)," ")=0," ",IFERROR(VLOOKUP($K9,'Calc - Crops'!$L$24:$Y$47,10,FALSE)/$P9," ")) | X9: =IF(IFERROR(VLOOKUP($K9,'Calc - Crops'!$L$24:$Y$47,9,FALSE)," ")=0," ",IFERROR(VLOOKUP($K9,'Calc - Crops'!$L$24:$Y$47,9,FALSE)/$P9," ")) | Y9: =IFERROR(VLOOKUP($C9,'Calc - Crops'!$L$24:$Y$47,2,FALSE)/1000, " ") | Z9: =IF(E9<>"",SUMIFS('Input data - Other'!$F:$F,'Input data - Other'!$B:$B,Crops!Z$6,'Input data - Other'!$D:$D,Crops!$E9),"") | AA9: =IF(F9<>"",SUMIFS('Input data - Other'!$F:$F,'Input data - Other'!$B:$B,Crops!AA$6,'Input data - Other'!$D:$D,Crops!$E9),"")
B10: =IF(Y10=0,"\I:","DMD") -> \I: | C10: AFOCRPOFIRICWTRE0 | D10: Afolu Crops Open Field Rice Existing 0 | E10: Open Field | F10: Rice | G10: Mton | H10: kha | I10: Annual | K10: =IF(Y10=0,"\I:",C10) -> \I: | L10: Afolu Crops Open Field Rice Existing 0 | M10: WTRAFO | N10: AFOCRPRICDEM | P10: =IF(IFERROR(VLOOKUP($K10,'Calc - Crops'!$L$24:$Y$47,8,FALSE)," ")=0," ",IFERROR(VLOOKUP($K10,'Calc - Crops'!$L$24:$Y$47,8,FALSE)/1000," ")) | Q10: =IF(IFERROR(P10/(IFERROR(VLOOKUP(F10,'Calc - water'!$B$39:$G$48,6,FALSE),"")*IFERROR(VLOOKUP(E10,DefaultAFOLU!$C$32:$G$39,5,FALSE),"")),"")=0," ",IFERROR(P10/(IFERROR(VLOOKUP(F10,'Calc - water'!$B$39:$G$48,6,FALSE),"")*IFERROR(VLOOKUP(E10,DefaultAFOLU!$C$32:$G$39,5,FALSE),"")),"")) | R10: 1 | S10: 4 | T10: =IF(Y10=0,Intro!$B$16+1,"") -> 2023 | V10: =IF(IFERROR(VLOOKUP($K10,'Calc - Crops'!$L$24:$Y$47,11,FALSE)," ")=0," ",IFERROR(VLOOKUP($K10,'Calc - Crops'!$L$24:$Y$47,11,FALSE)/$P10," ")) | W10: =IF(IFERROR(VLOOKUP($K10,'Calc - Crops'!$L$24:$Y$47,10,FALSE)," ")=0," ",IFERROR(VLOOKUP($K10,'Calc - Crops'!$L$24:$Y$47,10,FALSE)/$P10," ")) | X10: =IF(IFERROR(VLOOKUP($K10,'Calc - Crops'!$L$24:$Y$47,9,FALSE)," ")=0," ",IFERROR(VLOOKUP($K10,'Calc - Crops'!$L$24:$Y$47,9,FALSE)/$P10," ")) | Y10: =IFERROR(VLOOKUP($C10,'Calc - Crops'!$L$24:$Y$47,2,FALSE)/1000, " ") -> 0 | Z10: =IF(E10<>"",SUMIFS('Input data - Other'!$F:$F,'Input data - Other'!$B:$B,Crops!Z$6,'Input data - Other'!$D:$D,Crops!$E10),"") -> 0.156 | AA10: =IF(F10<>"",SUMIFS('Input data - Other'!$F:$F,'Input data - Other'!$B:$B,Crops!AA$6,'Input data - Other'!$D:$D,Crops!$E10),"") -> 0
B11: \I: | K11: =IF(Y10=0,"\I:"," ") -> \I: | O11: RICSTR | P11: =IF(IFERROR(VLOOKUP($K11,'Calc - Crops'!$L$24:$Y$47,8,FALSE)," ")=0," ",IFERROR(VLOOKUP($K11,'Calc - Crops'!$L$24:$Y$47,8,FALSE)/1000," ")) | Q11: =IF(IFERROR(P11/(IFERROR(VLOOKUP(F11,'Calc - water'!$B$39:$G$48,6,FALSE),"")*IFERROR(VLOOKUP(E11,DefaultAFOLU!$C$32:$G$39,5,FALSE),"")),"")=0," ",IFERROR(P11/(IFERROR(VLOOKUP(F11,'Calc - water'!$B$39:$G$48,6,FALSE),"")*IFERROR(VLOOKUP(E11,DefaultAFOLU!$C$32:$G$39,5,FALSE),"")),"")) | T11: =IF(Y11=0,Intro!$B$16+1,"") | U11: =IFERROR(VLOOKUP(O11,DefaultAFOLU!$D$42:$G$50,4,TRUE)," ") -> 0.3 | V11: =IF(IFERROR(VLOOKUP($K11,'Calc - Crops'!$L$24:$Y$47,11,FALSE)," ")=0," ",IFERROR(VLOOKUP($K11,'Calc - Crops'!$L$24:$Y$47,11,FALSE)/$P11," ")) | W11: =IF(IFERROR(VLOOKUP($K11,'Calc - Crops'!$L$24:$Y$47,10,FALSE)," ")=0," ",IFERROR(VLOOKUP($K11,'Calc - Crops'!$L$24:$Y$47,10,FALSE)/$P11," ")) | X11: =IF(IFERROR(VLOOKUP($K11,'Calc - Crops'!$L$24:$Y$47,9,FALSE)," ")=0," ",IFERROR(VLOOKUP($K11,'Calc - Crops'!$L$24:$Y$47,9,FALSE)/$P11," ")) | Y11: =IFERROR(VLOOKUP($C11,'Calc - Crops'!$L$24:$Y$47,2,FALSE)/1000, " ") | Z11: =IF(E11<>"",SUMIFS('Input data - Other'!$F:$F,'Input data - Other'!$B:$B,Crops!Z$6,'Input data - Other'!$D:$D,Crops!$E11),"") | AA11: =IF(F11<>"",SUMIFS('Input data - Other'!$F:$F,'Input data - Other'!$B:$B,Crops!AA$6,'Input data - Other'!$D:$D,Crops!$E11),"")
B12: =IF(Y12=0,"\I:","DMD") -> DMD | C12: AFOCRPOFILEGWTRE0 | D12: Afolu Crops Open Field Legumes Existing 0 | E12: Open Field | F12: Legumes | G12: Mton | H12: kha | I12: Annual | K12: =IF(Y12=0,"\I:",C12) -> AFOCRPOFILEGWTRE0 | L12: Afolu Crops Open Field Legumes Existing 0 | M12: WTRAFO | N12: AFOCRPLEGDEM | P12: =IF(IFERROR(VLOOKUP($K12,'Calc - Crops'!$L$24:$Y$47,8,FALSE)," ")=0," ",IFERROR(VLOOKUP($K12,'Calc - Crops'!$L$24:$Y$47,8,FALSE)/1000," ")) -> 0.00033219646 | Q12: =IF(IFERROR(P12/(IFERROR(VLOOKUP(F12,'Calc - water'!$B$39:$G$48,6,FALSE),"")*IFERROR(VLOOKUP(E12,DefaultAFOLU!$C$32:$G$39,5,FALSE),"")),"")=0," ",IFERROR(P12/(IFERROR(VLOOKUP(F12,'Calc - water'!$B$39:$G$48,6,FALSE),"")*IFERROR(VLOOKUP(E12,DefaultAFOLU!$C$32:$G$39,5,FALSE),"")),"")) -> 0.0067046943 | R12: 1 | S12: 4 | T12: =IF(Y12=0,Intro!$B$16+1,"") | V12: =IF(IFERROR(VLOOKUP($K12,'Calc - Crops'!$L$24:$Y$47,11,FALSE)," ")=0," ",IFERROR(VLOOKUP($K12,'Calc - Crops'!$L$24:$Y$47,11,FALSE)/$P12," ")) -> 24588.015 | W12: =IF(IFERROR(VLOOKUP($K12,'Calc - Crops'!$L$24:$Y$47,10,FALSE)," ")=0," ",IFERROR(VLOOKUP($K12,'Calc - Crops'!$L$24:$Y$47,10,FALSE)/$P12," ")) -> 1.2586856 | X12: =IF(IFERROR(VLOOKUP($K12,'Calc - Crops'!$L$24:$Y$47,9,FALSE)," ")=0," ",IFERROR(VLOOKUP($K12,'Calc - Crops'!$L$24:$Y$47,9,FALSE)/$P12," ")) -> 34.314626 | Y12: =IFERROR(VLOOKUP($C12,'Calc - Crops'!$L$24:$Y$47,2,FALSE)/1000, " ") -> 58.08 | Z12: =IF(E12<>"",SUMIFS('Input data - Other'!$F:$F,'Input data - Other'!$B:$B,Crops!Z$6,'Input data - Other'!$D:$D,Crops!$E12),"") -> 0.156 | AA12: =IF(F12<>"",SUMIFS('Input data - Other'!$F:$F,'Input data - Other'!$B:$B,Crops!AA$6,'Input data - Other'!$D:$D,Crops!$E12),"") -> 0
B13: \I: | K13: =IF(Y12=0,"\I:"," ") | O13: LEGWSB | P13: =IF(IFERROR(VLOOKUP($K13,'Calc - Crops'!$L$24:$Y$47,8,FALSE)," ")=0," ",IFERROR(VLOOKUP($K13,'Calc - Crops'!$L$24:$Y$47,8,FALSE)/1000," ")) | Q13: =IF(IFERROR(P13/(IFERROR(VLOOKUP(F13,'Calc - water'!$B$39:$G$48,6,FALSE),"")*IFERROR(VLOOKUP(E13,DefaultAFOLU!$C$32:$G$39,5,FALSE),"")),"")=0," ",IFERROR(P13/(IFERROR(VLOOKUP(F13,'Calc - water'!$B$39:$G$48,6,FALSE),"")*IFERROR(VLOOKUP(E13,DefaultAFOLU!$C$32:$G$39,5,FALSE),"")),"")) | T13: =IF(Y13=0,Intro!$B$16+1,"") | U13: =IFERROR(VLOOKUP(O13,DefaultAFOLU!$D$42:$G$50,4,TRUE)," ") -> 0.3 | V13: =IF(IFERROR(VLOOKUP($K13,'Calc - Crops'!$L$24:$Y$47,11,FALSE)," ")=0," ",IFERROR(VLOOKUP($K13,'Calc - Crops'!$L$24:$Y$47,11,FALSE)/$P13," ")) | W13: =IF(IFERROR(VLOOKUP($K13,'Calc - Crops'!$L$24:$Y$47,10,FALSE)," ")=0," ",IFERROR(VLOOKUP($K13,'Calc - Crops'!$L$24:$Y$47,10,FALSE)/$P13," ")) | X13: =IF(IFERROR(VLOOKUP($K13,'Calc - Crops'!$L$24:$Y$47,9,FALSE)," ")=0," ",IFERROR(VLOOKUP($K13,'Calc - Crops'!$L$24:$Y$47,9,FALSE)/$P13," ")) | Y13: =IFERROR(VLOOKUP($C13,'Calc - Crops'!$L$24:$Y$47,2,FALSE)/1000, " ") | Z13: =IF(E13<>"",SUMIFS('Input data - Other'!$F:$F,'Input data - Other'!$B:$B,Crops!Z$6,'Input data - Other'!$D:$D,Crops!$E13),"") | AA13: =IF(F13<>"",SUMIFS('Input data - Other'!$F:$F,'Input data - Other'!$B:$B,Crops!AA$6,'Input data - Other'!$D:$D,Crops!$E13),"")
B14: =IF(Y14=0,"\I:","DMD") -> DMD | C14: AFOCRPOFISEEWTRE0 | D14: Afolu Crops Open Field Seeds Existing 0 | E14: Open Field | F14: Seeds | G14: Mton | H14: kha | I14: Annual | K14: =IF(Y14=0,"\I:",C14) -> AFOCRPOFISEEWTRE0 | L14: Afolu Crops Open Field Seeds Existing 0 | M14: WTRAFO | N14: AFOCRPSEEDEM | P14: =IF(IFERROR(VLOOKUP($K14,'Calc - Crops'!$L$24:$Y$47,8,FALSE)," ")=0," ",IFERROR(VLOOKUP($K14,'Calc - Crops'!$L$24:$Y$47,8,FALSE)/1000," ")) -> 0.00033561 | Q14: =IF(IFERROR(P14/(IFERROR(VLOOKUP(F14,'Calc - water'!$B$39:$G$48,6,FALSE),"")*IFERROR(VLOOKUP(E14,DefaultAFOLU!$C$32:$G$39,5,FALSE),"")),"")=0," ",IFERROR(P14/(IFERROR(VLOOKUP(F14,'Calc - water'!$B$39:$G$48,6,FALSE),"")*IFERROR(VLOOKUP(E14,DefaultAFOLU!$C$32:$G$39,5,FALSE),"")),"")) -> 0.0053286797 | R14: 1 | S14: 4 | T14: =IF(Y14=0,Intro!$B$16+1,"") | V14: =IF(IFERROR(VLOOKUP($K14,'Calc - Crops'!$L$24:$Y$47,11,FALSE)," ")=0," ",IFERROR(VLOOKUP($K14,'Calc - Crops'!$L$24:$Y$47,11,FALSE)/$P14," ")) -> 24337.927 | W14: =IF(IFERROR(VLOOKUP($K14,'Calc - Crops'!$L$24:$Y$47,10,FALSE)," ")=0," ",IFERROR(VLOOKUP($K14,'Calc - Crops'!$L$24:$Y$47,10,FALSE)/$P14," ")) -> 1.2458834 | X14: =IF(IFERROR(VLOOKUP($K14,'Calc - Crops'!$L$24:$Y$47,9,FALSE)," ")=0," ",IFERROR(VLOOKUP($K14,'Calc - Crops'!$L$24:$Y$47,9,FALSE)/$P14," ")) -> 33.965607 | Y14: =IFERROR(VLOOKUP($C14,'Calc - Crops'!$L$24:$Y$47,2,FALSE)/1000, " ") -> 127.38 | Z14: =IF(E14<>"",SUMIFS('Input data - Other'!$F:$F,'Input data - Other'!$B:$B,Crops!Z$6,'Input data - Other'!$D:$D,Crops!$E14),"") -> 0.156 | AA14: =IF(F14<>"",SUMIFS('Input data - Other'!$F:$F,'Input data - Other'!$B:$B,Crops!AA$6,'Input data - Other'!$D:$D,Crops!$E14),"") -> 0
B15: \I: | K15: =IF(Y14=0,"\I:"," ") | O15: SEEWSB | P15: =IF(IFERROR(VLOOKUP($K15,'Calc - Crops'!$L$24:$Y$47,8,FALSE)," ")=0," ",IFERROR(VLOOKUP($K15,'Calc - Crops'!$L$24:$Y$47,8,FALSE)/1000," ")) | Q15: =IF(IFERROR(P15/(IFERROR(VLOOKUP(F15,'Calc - water'!$B$39:$G$48,6,FALSE),"")*IFERROR(VLOOKUP(E15,DefaultAFOLU!$C$32:$G$39,5,FALSE),"")),"")=0," ",IFERROR(P15/(IFERROR(VLOOKUP(F15,'Calc - water'!$B$39:$G$48,6,FALSE),"")*IFERROR(VLOOKUP(E15,DefaultAFOLU!$C$32:$G$39,5,FALSE),"")),"")) | T15: =IF(Y15=0,Intro!$B$16+1,"") | U15: =IFERROR(VLOOKUP(O15,DefaultAFOLU!$D$42:$G$50,4,TRUE)," ") -> 0.3 | V15: =IF(IFERROR(VLOOKUP($K15,'Calc - Crops'!$L$24:$Y$47,11,FALSE)," ")=0," ",IFERROR(VLOOKUP($K15,'Calc - Crops'!$L$24:$Y$47,11,FALSE)/$P15," ")) | W15: =IF(IFERROR(VLOOKUP($K15,'Calc - Crops'!$L$24:$Y$47,10,FALSE)," ")=0," ",IFERROR(VLOOKUP($K15,'Calc - Crops'!$L$24:$Y$47,10,FALSE)/$P15," ")) | X15: =IF(IFERROR(VLOOKUP($K15,'Calc - Crops'!$L$24:$Y$47,9,FALSE)," ")=0," ",IFERROR(VLOOKUP($K15,'Calc - Crops'!$L$24:$Y$47,9,FALSE)/$P15," ")) | Y15: =IFERROR(VLOOKUP($C15,'Calc - Crops'!$L$24:$Y$47,2,FALSE)/1000, " ") | Z15: =IF(E15<>"",SUMIFS('Input data - Other'!$F:$F,'Input data - Other'!$B:$B,Crops!Z$6,'Input data - Other'!$D:$D,Crops!$E15),"") | AA15: =IF(F15<>"",SUMIFS('Input data - Other'!$F:$F,'Input data - Other'!$B:$B,Crops!AA$6,'Input data - Other'!$D:$D,Crops!$E15),"")
B16: =IF(Y16=0,"\I:","DMD") -> \I: | C16: AFOCRPOFIFCRWTRE0 | D16: Afolu Crops Open Field Fiber crops Existing 0 | E16: Open Field | F16: Fiber crops | G16: Mton | H16: kha | I16: Annual | K16: =IF(Y16=0,"\I:",C16) -> \I: | L16: Afolu Crops Open Field Fiber crops Existing 0 | M16: WTRAFO | N16: AFOCRPFCRDEM | P16: =IF(IFERROR(VLOOKUP($K16,'Calc - Crops'!$L$24:$Y$47,8,FALSE)," ")=0," ",IFERROR(VLOOKUP($K16,'Calc - Crops'!$L$24:$Y$47,8,FALSE)/1000," ")) | Q16: =IF(IFERROR(P16/(IFERROR(VLOOKUP(F16,'Calc - water'!$B$39:$G$48,6,FALSE),"")*IFERROR(VLOOKUP(E16,DefaultAFOLU!$C$32:$G$39,5,FALSE),"")),"")=0," ",IFERROR(P16/(IFERROR(VLOOKUP(F16,'Calc - water'!$B$39:$G$48,6,FALSE),"")*IFERROR(VLOOKUP(E16,DefaultAFOLU!$C$32:$G$39,5,FALSE),"")),"")) | R16: 1 | S16: 4 | T16: =IF(Y16=0,Intro!$B$16+1,"") -> 2023 | V16: =IF(IFERROR(VLOOKUP($K16,'Calc - Crops'!$L$24:$Y$47,11,FALSE)," ")=0," ",IFERROR(VLOOKUP($K16,'Calc - Crops'!$L$24:$Y$47,11,FALSE)/$P16," ")) | W16: =IF(IFERROR(VLOOKUP($K16,'Calc - Crops'!$L$24:$Y$47,10,FALSE)," ")=0," ",IFERROR(VLOOKUP($K16,'Calc - Crops'!$L$24:$Y$47,10,FALSE)/$P16," ")) | X16: =IF(IFERROR(VLOOKUP($K16,'Calc - Crops'!$L$24:$Y$47,9,FALSE)," ")=0," ",IFERROR(VLOOKUP($K16,'Calc - Crops'!$L$24:$Y$47,9,FALSE)/$P16," ")) | Y16: =IFERROR(VLOOKUP($C16,'Calc - Crops'!$L$24:$Y$47,2,FALSE)/1000, " ") -> 0 | Z16: =IF(E16<>"",SUMIFS('Input data - Other'!$F:$F,'Input data - Other'!$B:$B,Crops!Z$6,'Input data - Other'!$D:$D,Crops!$E16),"") -> 0.156 | AA16: =IF(F16<>"",SUMIFS('Input data - Other'!$F:$F,'Input data - Other'!$B:$B,Crops!AA$6,'Input data - Other'!$D:$D,Crops!$E16),"") -> 0
B17: \I: | K17: =IF(Y16=0,"\I:"," ") -> \I: | O17: FCRWSB | P17: =IF(IFERROR(VLOOKUP($K17,'Calc - Crops'!$L$24:$Y$47,8,FALSE)," ")=0," ",IFERROR(VLOOKUP($K17,'Calc - Crops'!$L$24:$Y$47,8,FALSE)/1000," ")) | Q17: =IF(IFERROR(P17/(IFERROR(VLOOKUP(F17,'Calc - water'!$B$39:$G$48,6,FALSE),"")*IFERROR(VLOOKUP(E17,DefaultAFOLU!$C$32:$G$39,5,FALSE),"")),"")=0," ",IFERROR(P17/(IFERROR(VLOOKUP(F17,'Calc - water'!$B$39:$G$48,6,FALSE),"")*IFERROR(VLOOKUP(E17,DefaultAFOLU!$C$32:$G$39,5,FALSE),"")),"")) | T17: =IF(Y17=0,Intro!$B$16+1,"") | U17: =IFERROR(VLOOKUP(O17,DefaultAFOLU!$D$42:$G$50,4,TRUE)," ") -> 0.3 | V17: =IF(IFERROR(VLOOKUP($K17,'Calc - Crops'!$L$24:$Y$47,11,FALSE)," ")=0," ",IFERROR(VLOOKUP($K17,'Calc - Crops'!$L$24:$Y$47,11,FALSE)/$P17," ")) | W17: =IF(IFERROR(VLOOKUP($K17,'Calc - Crops'!$L$24:$Y$47,10,FALSE)," ")=0," ",IFERROR(VLOOKUP($K17,'Calc - Crops'!$L$24:$Y$47,10,FALSE)/$P17," ")) | X17: =IF(IFERROR(VLOOKUP($K17,'Calc - Crops'!$L$24:$Y$47,9,FALSE)," ")=0," ",IFERROR(VLOOKUP($K17,'Calc - Crops'!$L$24:$Y$47,9,FALSE)/$P17," ")) | Y17: =IFERROR(VLOOKUP($C17,'Calc - Crops'!$L$24:$Y$47,2,FALSE)/1000, " ") | Z17: =IF(E17<>"",SUMIFS('Input data - Other'!$F:$F,'Input data - Other'!$B:$B,Crops!Z$6,'Input data - Other'!$D:$D,Crops!$E17),"") | AA17: =IF(F17<>"",SUMIFS('Input data - Other'!$F:$F,'Input data - Other'!$B:$B,Crops!AA$6,'Input data - Other'!$D:$D,Crops!$E17),"")
B18: =IF(Y18=0,"\I:","DMD") -> DMD | C18: AFOCRPOFIVEGWTRE0 | D18: Afolu Crops Open Field Vegetables Existing 0 | E18: Open Field | F18: Vegetables | G18: Mton | H18: kha | I18: Annual | K18: =IF(Y18=0,"\I:",C18) -> AFOCRPOFIVEGWTRE0 | L18: Afolu Crops Open Field Vegetables Existing 0 | M18: WTRAFO | N18: AFOCRPVEGDEM | P18: =IF(IFERROR(VLOOKUP($K18,'Calc - Crops'!$L$24:$Y$47,8,FALSE)," ")=0," ",IFERROR(VLOOKUP($K18,'Calc - Crops'!$L$24:$Y$47,8,FALSE)/1000," ")) -> 0.0047459946 | Q18: =IF(IFERROR(P18/(IFERROR(VLOOKUP(F18,'Calc - water'!$B$39:$G$48,6,FALSE),"")*IFERROR(VLOOKUP(E18,DefaultAFOLU!$C$32:$G$39,5,FALSE),"")),"")=0," ",IFERROR(P18/(IFERROR(VLOOKUP(F18,'Calc - water'!$B$39:$G$48,6,FALSE),"")*IFERROR(VLOOKUP(E18,DefaultAFOLU!$C$32:$G$39,5,FALSE),"")),"")) -> 0.0056531788 | R18: 1 | S18: 4 | T18: =IF(Y18=0,Intro!$B$16+1,"") | V18: =IF(IFERROR(VLOOKUP($K18,'Calc - Crops'!$L$24:$Y$47,11,FALSE)," ")=0," ",IFERROR(VLOOKUP($K18,'Calc - Crops'!$L$24:$Y$47,11,FALSE)/$P18," ")) -> 1721.0411 | W18: =IF(IFERROR(VLOOKUP($K18,'Calc - Crops'!$L$24:$Y$47,10,FALSE)," ")=0," ",IFERROR(VLOOKUP($K18,'Calc - Crops'!$L$24:$Y$47,10,FALSE)/$P18," ")) -> 0.088101853 | X18: =IF(IFERROR(VLOOKUP($K18,'Calc - Crops'!$L$24:$Y$47,9,FALSE)," ")=0," ",IFERROR(VLOOKUP($K18,'Calc - Crops'!$L$24:$Y$47,9,FALSE)/$P18," ")) -> 2.4018564 | Y18: =IFERROR(VLOOKUP($C18,'Calc - Crops'!$L$24:$Y$47,2,FALSE)/1000, " ") -> 2.576 | Z18: =IF(E18<>"",SUMIFS('Input data - Other'!$F:$F,'Input data - Other'!$B:$B,Crops!Z$6,'Input data - Other'!$D:$D,Crops!$E18),"") -> 0.156 | AA18: =IF(F18<>"",SUMIFS('Input data - Other'!$F:$F,'Input data - Other'!$B:$B,Crops!AA$6,'Input data - Other'!$D:$D,Crops!$E18),"") -> 0
B19: \I: | K19: =IF(Y18=0,"\I:"," ") | O19: VEGWSB | P19: =IF(IFERROR(VLOOKUP($K19,'Calc - Crops'!$L$24:$Y$47,8,FALSE)," ")=0," ",IFERROR(VLOOKUP($K19,'Calc - Crops'!$L$24:$Y$47,8,FALSE)/1000," ")) | Q19: =IF(IFERROR(P19/(IFERROR(VLOOKUP(F19,'Calc - water'!$B$39:$G$48,6,FALSE),"")*IFERROR(VLOOKUP(E19,DefaultAFOLU!$C$32:$G$39,5,FALSE),"")),"")=0," ",IFERROR(P19/(IFERROR(VLOOKUP(F19,'Calc - water'!$B$39:$G$48,6,FALSE),"")*IFERROR(VLOOKUP(E19,DefaultAFOLU!$C$32:$G$39,5,FALSE),"")),"")) | T19: =IF(Y19=0,Intro!$B$16+1,"") | U19: =IFERROR(VLOOKUP(O19,DefaultAFOLU!$D$42:$G$50,4,TRUE)," ") -> 0.1 | V19: =IF(IFERROR(VLOOKUP($K19,'Calc - Crops'!$L$24:$Y$47,11,FALSE)," ")=0," ",IFERROR(VLOOKUP($K19,'Calc - Crops'!$L$24:$Y$47,11,FALSE)/$P19," ")) | W19: =IF(IFERROR(VLOOKUP($K19,'Calc - Crops'!$L$24:$Y$47,10,FALSE)," ")=0," ",IFERROR(VLOOKUP($K19,'Calc - Crops'!$L$24:$Y$47,10,FALSE)/$P19," ")) | X19: =IF(IFERROR(VLOOKUP($K19,'Calc - Crops'!$L$24:$Y$47,9,FALSE)," ")=0," ",IFERROR(VLOOKUP($K19,'Calc - Crops'!$L$24:$Y$47,9,FALSE)/$P19," ")) | Y19: =IFERROR(VLOOKUP($C19,'Calc - Crops'!$L$24:$Y$47,2,FALSE)/1000, " ") | Z19: =IF(E19<>"",SUMIFS('Input data - Other'!$F:$F,'Input data - Other'!$B:$B,Crops!Z$6,'Input data - Other'!$D:$D,Crops!$E19),"") | AA19: =IF(F19<>"",SUMIFS('Input data - Other'!$F:$F,'Input data - Other'!$B:$B,Crops!AA$6,'Input data - Other'!$D:$D,Crops!$E19),"")
B20: =IF(Y20=0,"\I:","DMD") -> DMD | C20: AFOCRPOFIWCRWTRE0 | D20: Afolu Crops Open Field Woody crops Existing 0 | E20: Open Field | F20: Woody crops | G20: Mton | H20: kha | I20: Annual | K20: =IF(Y20=0,"\I:",C20) -> AFOCRPOFIWCRWTRE0 | L20: Afolu Crops Open Field Woody crops Existing 0 | M20: WTRAFO | N20: AFOCRPWCRDEM | P20: =IF(IFERROR(VLOOKUP($K20,'Calc - Crops'!$L$24:$Y$47,8,FALSE)," ")=0," ",IFERROR(VLOOKUP($K20,'Calc - Crops'!$L$24:$Y$47,8,FALSE)/1000," ")) -> 0.0015218322 | Q20: =IF(IFERROR(P20/(IFERROR(VLOOKUP(F20,'Calc - water'!$B$39:$G$48,6,FALSE),"")*IFERROR(VLOOKUP(E20,DefaultAFOLU!$C$32:$G$39,5,FALSE),"")),"")=0," ",IFERROR(P20/(IFERROR(VLOOKUP(F20,'Calc - water'!$B$39:$G$48,6,FALSE),"")*IFERROR(VLOOKUP(E20,DefaultAFOLU!$C$32:$G$39,5,FALSE),"")),"")) -> 15.218322 | R20: 1 | S20: 4 | T20: =IF(Y20=0,Intro!$B$16+1,"") | V20: =IF(IFERROR(VLOOKUP($K20,'Calc - Crops'!$L$24:$Y$47,11,FALSE)," ")=0," ",IFERROR(VLOOKUP($K20,'Calc - Crops'!$L$24:$Y$47,11,FALSE)/$P20," ")) -> 5367.2486 | W20: =IF(IFERROR(VLOOKUP($K20,'Calc - Crops'!$L$24:$Y$47,10,FALSE)," ")=0," ",IFERROR(VLOOKUP($K20,'Calc - Crops'!$L$24:$Y$47,10,FALSE)/$P20," ")) -> 0.27475494 | X20: =IF(IFERROR(VLOOKUP($K20,'Calc - Crops'!$L$24:$Y$47,9,FALSE)," ")=0," ",IFERROR(VLOOKUP($K20,'Calc - Crops'!$L$24:$Y$47,9,FALSE)/$P20," ")) -> 7.4904432 | Y20: =IFERROR(VLOOKUP($C20,'Calc - Crops'!$L$24:$Y$47,2,FALSE)/1000, " ") -> 2.29 | Z20: =IF(E20<>"",SUMIFS('Input data - Other'!$F:$F,'Input data - Other'!$B:$B,Crops!Z$6,'Input data - Other'!$D:$D,Crops!$E20),"") -> 0.156 | AA20: =IF(F20<>"",SUMIFS('Input data - Other'!$F:$F,'Input data - Other'!$B:$B,Crops!AA$6,'Input data - Other'!$D:$D,Crops!$E20),"") -> 0
B21: \I: | K21: =IF(Y20=0,"\I:"," ") | O21: WCRWOC | P21: =IF(IFERROR(VLOOKUP($K21,'Calc - Crops'!$L$24:$Y$47,8,FALSE)," ")=0," ",IFERROR(VLOOKUP($K21,'Calc - Crops'!$L$24:$Y$47,8,FALSE)/1000," ")) | Q21: =IF(IFERROR(P21/(IFERROR(VLOOKUP(F21,'Calc - water'!$B$39:$G$48,6,FALSE),"")*IFERROR(VLOOKUP(E21,DefaultAFOLU!$C$32:$G$39,5,FALSE),"")),"")=0," ",IFERROR(P21/(IFERROR(VLOOKUP(F21,'Calc - water'!$B$39:$G$48,6,FALSE),"")*IFERROR(VLOOKUP(E21,DefaultAFOLU!$C$32:$G$39,5,FALSE),"")),"")) | T21: =IF(Y21=0,Intro!$B$16+1,"") | U21: =IFERROR(VLOOKUP(O21,DefaultAFOLU!$D$42:$G$50,4,TRUE)," ") -> 0.1 | V21: =IF(IFERROR(VLOOKUP($K21,'Calc - Crops'!$L$24:$Y$47,11,FALSE)," ")=0," ",IFERROR(VLOOKUP($K21,'Calc - Crops'!$L$24:$Y$47,11,FALSE)/$P21," ")) | W21: =IF(IFERROR(VLOOKUP($K21,'Calc - Crops'!$L$24:$Y$47,10,FALSE)," ")=0," ",IFERROR(VLOOKUP($K21,'Calc - Crops'!$L$24:$Y$47,10,FALSE)/$P21," ")) | X21: =IF(IFERROR(VLOOKUP($K21,'Calc - Crops'!$L$24:$Y$47,9,FALSE)," ")=0," ",IFERROR(VLOOKUP($K21,'Calc - Crops'!$L$24:$Y$47,9,FALSE)/$P21," ")) | Y21: =IFERROR(VLOOKUP($C21,'Calc - Crops'!$L$24:$Y$47,2,FALSE)/1000, " ") | Z21: =IF(E21<>"",SUMIFS('Input data - Other'!$F:$F,'Input data - Other'!$B:$B,Crops!Z$6,'Input data - Other'!$D:$D,Crops!$E21),"") | AA21: =IF(F21<>"",SUMIFS('Input data - Other'!$F:$F,'Input data - Other'!$B:$B,Crops!AA$6,'Input data - Other'!$D:$D,Crops!$E21),"")
B22: =IF(Y22=0,"\I:","DMD") -> DMD | C22: AFOCRPOFIROOWTRE0 | D22: Afolu Crops Open Field Roots Existing 0 | E22: Open Field | F22: Roots | G22: Mton | H22: kha | I22: Annual | K22: =IF(Y22=0,"\I:",C22) -> AFOCRPOFIROOWTRE0 | L22: Afolu Crops Open Field Roots Existing 0 | M22: WTRAFO | N22: AFOCRPROODEM | P22: =IF(IFERROR(VLOOKUP($K22,'Calc - Crops'!$L$24:$Y$47,8,FALSE)," ")=0," ",IFERROR(VLOOKUP($K22,'Calc - Crops'!$L$24:$Y$47,8,FALSE)/1000," ")) -> 0.0052539044 | Q22: =IF(IFERROR(P22/(IFERROR(VLOOKUP(F22,'Calc - water'!$B$39:$G$48,6,FALSE),"")*IFERROR(VLOOKUP(E22,DefaultAFOLU!$C$32:$G$39,5,FALSE),"")),"")=0," ",IFERROR(P22/(IFERROR(VLOOKUP(F22,'Calc - water'!$B$39:$G$48,6,FALSE),"")*IFERROR(VLOOKUP(E22,DefaultAFOLU!$C$32:$G$39,5,FALSE),"")),"")) -> 0.015959959 | R22: 1 | S22: 4 | T22: =IF(Y22=0,Intro!$B$16+1,"") | V22: =IF(IFERROR(VLOOKUP($K22,'Calc - Crops'!$L$24:$Y$47,11,FALSE)," ")=0," ",IFERROR(VLOOKUP($K22,'Calc - Crops'!$L$24:$Y$47,11,FALSE)/$P22," ")) -> 1554.6632 | W22: =IF(IFERROR(VLOOKUP($K22,'Calc - Crops'!$L$24:$Y$47,10,FALSE)," ")=0," ",IFERROR(VLOOKUP($K22,'Calc - Crops'!$L$24:$Y$47,10,FALSE)/$P22," ")) -> 0.079584796 | X22: =IF(IFERROR(VLOOKUP($K22,'Calc - Crops'!$L$24:$Y$47,9,FALSE)," ")=0," ",IFERROR(VLOOKUP($K22,'Calc - Crops'!$L$24:$Y$47,9,FALSE)/$P22," ")) -> 2.1696621 | Y22: =IFERROR(VLOOKUP($C22,'Calc - Crops'!$L$24:$Y$47,2,FALSE)/1000, " ") -> 54.41 | Z22: =IF(E22<>"",SUMIFS('Input data - Other'!$F:$F,'Input data - Other'!$B:$B,Crops!Z$6,'Input data - Other'!$D:$D,Crops!$E22),"") -> 0.156 | AA22: =IF(F22<>"",SUMIFS('Input data - Other'!$F:$F,'Input data - Other'!$B:$B,Crops!AA$6,'Input data - Other'!$D:$D,Crops!$E22),"") -> 0
B23: \I: | K23: =IF(Y22=0,"\I:"," ") | O23: ROOWSB | P23: =IF(IFERROR(VLOOKUP($K23,'Calc - Crops'!$L$24:$Y$47,8,FALSE)," ")=0," ",IFERROR(VLOOKUP($K23,'Calc - Crops'!$L$24:$Y$47,8,FALSE)/1000," ")) | Q23: =IF(IFERROR(P23/(IFERROR(VLOOKUP(F23,'Calc - water'!$B$39:$G$48,6,FALSE),"")*IFERROR(VLOOKUP(E23,DefaultAFOLU!$C$32:$G$39,5,FALSE),"")),"")=0," ",IFERROR(P23/(IFERROR(VLOOKUP(F23,'Calc - water'!$B$39:$G$48,6,FALSE),"")*IFERROR(VLOOKUP(E23,DefaultAFOLU!$C$32:$G$39,5,FALSE),"")),"")) | T23: =IF(Y23=0,Intro!$B$16+1,"") | U23: =IFERROR(VLOOKUP(O23,DefaultAFOLU!$D$42:$G$50,4,TRUE)," ") -> 0.3 | V23: =IF(IFERROR(VLOOKUP($K23,'Calc - Crops'!$L$24:$Y$47,11,FALSE)," ")=0," ",IFERROR(VLOOKUP($K23,'Calc - Crops'!$L$24:$Y$47,11,FALSE)/$P23," ")) | W23: =IF(IFERROR(VLOOKUP($K23,'Calc - Crops'!$L$24:$Y$47,10,FALSE)," ")=0," ",IFERROR(VLOOKUP($K23,'Calc - Crops'!$L$24:$Y$47,10,FALSE)/$P23," ")) | X23: =IF(IFERROR(VLOOKUP($K23,'Calc - Crops'!$L$24:$Y$47,9,FALSE)," ")=0," ",IFERROR(VLOOKUP($K23,'Calc - Crops'!$L$24:$Y$47,9,FALSE)/$P23," ")) | Y23: =IFERROR(VLOOKUP($C23,'Calc - Crops'!$L$24:$Y$47,2,FALSE)/1000, " ") | Z23: =IF(E23<>"",SUMIFS('Input data - Other'!$F:$F,'Input data - Other'!$B:$B,Crops!Z$6,'Input data - Other'!$D:$D,Crops!$E23),"") | AA23: =IF(F23<>"",SUMIFS('Input data - Other'!$F:$F,'Input data - Other'!$B:$B,Crops!AA$6,'Input data - Other'!$D:$D,Crops!$E23),"")
B24: =IF(Y24=0,"\I:","DMD") -> DMD | C24: AFOCRPOFIHAGWTRE0 | D24: Afolu Crops Open Field Herbs and greens Existing 0 | E24: Open Field | F24: Herbs and greens | G24: Mton | H24: kha | I24: Annual | K24: =IF(Y24=0,"\I:",C24) -> AFOCRPOFIHAGWTRE0 | L24: Afolu Crops Open Field Herbs and greens Existing 0 | M24: WTRAFO | N24: AFOCRPHAGDEM | P24: =IF(IFERROR(VLOOKUP($K24,'Calc - Crops'!$L$24:$Y$47,8,FALSE)," ")=0," ",IFERROR(VLOOKUP($K24,'Calc - Crops'!$L$24:$Y$47,8,FALSE)/1000," ")) -> 0.0014493778 | Q24: =IF(IFERROR(P24/(IFERROR(VLOOKUP(F24,'Calc - water'!$B$39:$G$48,6,FALSE),"")*IFERROR(VLOOKUP(E24,DefaultAFOLU!$C$32:$G$39,5,FALSE),"")),"")=0," ",IFERROR(P24/(IFERROR(VLOOKUP(F24,'Calc - water'!$B$39:$G$48,6,FALSE),"")*IFERROR(VLOOKUP(E24,DefaultAFOLU!$C$32:$G$39,5,FALSE),"")),"")) -> 14.493778 | R24: 1 | S24: 4 | T24: =IF(Y24=0,Intro!$B$16+1,"") | V24: =IF(IFERROR(VLOOKUP($K24,'Calc - Crops'!$L$24:$Y$47,11,FALSE)," ")=0," ",IFERROR(VLOOKUP($K24,'Calc - Crops'!$L$24:$Y$47,11,FALSE)/$P24," ")) -> 5635.5574 | W24: =IF(IFERROR(VLOOKUP($K24,'Calc - Crops'!$L$24:$Y$47,10,FALSE)," ")=0," ",IFERROR(VLOOKUP($K24,'Calc - Crops'!$L$24:$Y$47,10,FALSE)/$P24," ")) -> 0.28848995 | X24: =IF(IFERROR(VLOOKUP($K24,'Calc - Crops'!$L$24:$Y$47,9,FALSE)," ")=0," ",IFERROR(VLOOKUP($K24,'Calc - Crops'!$L$24:$Y$47,9,FALSE)/$P24," ")) -> 7.8648905 | Y24: =IFERROR(VLOOKUP($C24,'Calc - Crops'!$L$24:$Y$47,2,FALSE)/1000, " ") -> 4.84 | Z24: =IF(E24<>"",SUMIFS('Input data - Other'!$F:$F,'Input data - Other'!$B:$B,Crops!Z$6,'Input data - Other'!$D:$D,Crops!$E24),"") -> 0.156 | AA24: =IF(F24<>"",SUMIFS('Input data - Other'!$F:$F,'Input data - Other'!$B:$B,Crops!AA$6,'Input data - Other'!$D:$D,Crops!$E24),"") -> 0
B25: \I: | K25: =IF(Y24=0,"\I:"," ") | O25: HAGWSB | P25: =IF(IFERROR(VLOOKUP($K25,'Calc - Crops'!$L$24:$Y$47,8,FALSE)," ")=0," ",IFERROR(VLOOKUP($K25,'Calc - Crops'!$L$24:$Y$47,8,FALSE)/1000," ")) | Q25: =IF(IFERROR(P25/(IFERROR(VLOOKUP(F25,'Calc - water'!$B$39:$G$48,6,FALSE),"")*IFERROR(VLOOKUP(E25,DefaultAFOLU!$C$32:$G$39,5,FALSE),"")),"")=0," ",IFERROR(P25/(IFERROR(VLOOKUP(F25,'Calc - water'!$B$39:$G$48,6,FALSE),"")*IFERROR(VLOOKUP(E25,DefaultAFOLU!$C$32:$G$39,5,FALSE),"")),"")) | T25: =IF(Y25=0,Intro!$B$16+1,"") | U25: =IFERROR(VLOOKUP(O25,DefaultAFOLU!$D$42:$G$50,4,TRUE)," ") -> 0.3 | V25: =IF(IFERROR(VLOOKUP($K25,'Calc - Crops'!$L$24:$Y$47,11,FALSE)," ")=0," ",IFERROR(VLOOKUP($K25,'Calc - Crops'!$L$24:$Y$47,11,FALSE)/$P25," ")) | W25: =IF(IFERROR(VLOOKUP($K25,'Calc - Crops'!$L$24:$Y$47,10,FALSE)," ")=0," ",IFERROR(VLOOKUP($K25,'Calc - Crops'!$L$24:$Y$47,10,FALSE)/$P25," ")) | X25: =IF(IFERROR(VLOOKUP($K25,'Calc - Crops'!$L$24:$Y$47,9,FALSE)," ")=0," ",IFERROR(VLOOKUP($K25,'Calc - Crops'!$L$24:$Y$47,9,FALSE)/$P25," ")) | Y25: =IFERROR(VLOOKUP($C25,'Calc - Crops'!$L$24:$Y$47,2,FALSE)/1000, " ") | Z25: =IF(E25<>"",SUMIFS('Input data - Other'!$F:$F,'Input data - Other'!$B:$B,Crops!Z$6,'Input data - Other'!$D:$D,Crops!$E25),"") | AA25: =IF(F25<>"",SUMIFS('Input data - Other'!$F:$F,'Input data - Other'!$B:$B,Crops!AA$6,'Input data - Other'!$D:$D,Crops!$E25),"")
B26: DMD | C26: AFOCRPGRHLEGWTRE0 | D26: Afolu Crops Greenhouse Legumes Existing 0 | E26: Greenhouse | F26: Legumes | G26: Mton | H26: kha | I26: Annual | K26: =IF(Y12=0,"\I:",C26) -> AFOCRPGRHLEGWTRE0 | L26: Afolu Crops Greenhouse Legumes Existing 0 | M26: WTRAFO | N26: AFOCRPLEGDEM | P26: =IF(IFERROR(VLOOKUP($K26,'Calc - Crops'!$L$24:$Y$47,8,FALSE)," ")=0," ",IFERROR(VLOOKUP($K26,'Calc - Crops'!$L$24:$Y$47,8,FALSE)/1000," ")) -> 0.00099658939 | Q26: =IF(IFERROR(P26/(IFERROR(VLOOKUP(F26,'Calc - water'!$B$39:$G$48,6,FALSE),"")*IFERROR(VLOOKUP(E26,DefaultAFOLU!$C$32:$G$39,5,FALSE),"")),"")=0," ",IFERROR(P26/(IFERROR(VLOOKUP(F26,'Calc - water'!$B$39:$G$48,6,FALSE),"")*IFERROR(VLOOKUP(E26,DefaultAFOLU!$C$32:$G$39,5,FALSE),"")),"")) -> 0.026818777 | R26: 1 | S26: 4 | T26: =IF(Y26=0,Intro!$B$16+1,"") -> 2023 | V26: =IF(IFERROR(VLOOKUP($K26,'Calc - Crops'!$L$24:$Y$47,11,FALSE)," ")=0," ",IFERROR(VLOOKUP($K26,'Calc - Crops'!$L$24:$Y$47,11,FALSE)/$P26," ")) -> 8196.005 | W26: =IF(IFERROR(VLOOKUP($K26,'Calc - Crops'!$L$24:$Y$47,10,FALSE)," ")=0," ",IFERROR(VLOOKUP($K26,'Calc - Crops'!$L$24:$Y$47,10,FALSE)/$P26," ")) -> 0.41956188 | X26: =IF(IFERROR(VLOOKUP($K26,'Calc - Crops'!$L$24:$Y$47,9,FALSE)," ")=0," ",IFERROR(VLOOKUP($K26,'Calc - Crops'!$L$24:$Y$47,9,FALSE)/$P26," ")) -> 11.438209 | Y26: =IFERROR(VLOOKUP($C26,'Calc - Crops'!$L$24:$Y$47,2,FALSE)/1000, " ") -> 0 | Z26: =IF(E26<>"",SUMIFS('Input data - Other'!$F:$F,'Input data - Other'!$B:$B,Crops!Z$6,'Input data - Other'!$D:$D,Crops!$E26),"") -> 0.156 | AA26: =IF(F26<>"",SUMIFS('Input data - Other'!$F:$F,'Input data - Other'!$B:$B,Crops!AA$6,'Input data - Other'!$D:$D,Crops!$E26),"") -> 1000
B27: \I: | K27: =IF(Y12=0,"\I:"," ") | O27: LEGWSB | P27: =IF(IFERROR(VLOOKUP($K27,'Calc - Crops'!$L$24:$Y$47,8,FALSE)," ")=0," ",IFERROR(VLOOKUP($K27,'Calc - Crops'!$L$24:$Y$47,8,FALSE)/1000," ")) | Q27: =IF(IFERROR(P27/(IFERROR(VLOOKUP(F27,'Calc - water'!$B$39:$G$48,6,FALSE),"")*IFERROR(VLOOKUP(E27,DefaultAFOLU!$C$32:$G$39,5,FALSE),"")),"")=0," ",IFERROR(P27/(IFERROR(VLOOKUP(F27,'Calc - water'!$B$39:$G$48,6,FALSE),"")*IFERROR(VLOOKUP(E27,DefaultAFOLU!$C$32:$G$39,5,FALSE),"")),"")) | T27: =IF(Y27=0,Intro!$B$16+1,"") | U27: =IFERROR(VLOOKUP(O27,DefaultAFOLU!$D$42:$G$50,4,TRUE)," ") -> 0.3 | V27: =IF(IFERROR(VLOOKUP($K27,'Calc - Crops'!$L$24:$Y$47,11,FALSE)," ")=0," ",IFERROR(VLOOKUP($K27,'Calc - Crops'!$L$24:$Y$47,11,FALSE)/$P27," ")) | W27: =IF(IFERROR(VLOOKUP($K27,'Calc - Crops'!$L$24:$Y$47,10,FALSE)," ")=0," ",IFERROR(VLOOKUP($K27,'Calc - Crops'!$L$24:$Y$47,10,FALSE)/$P27," ")) | X27: =IF(IFERROR(VLOOKUP($K27,'Calc - Crops'!$L$24:$Y$47,9,FALSE)," ")=0," ",IFERROR(VLOOKUP($K27,'Calc - Crops'!$L$24:$Y$47,9,FALSE)/$P27," ")) | Y27: =IFERROR(VLOOKUP($C27,'Calc - Crops'!$L$24:$Y$47,2,FALSE)/1000, " ") | Z27: =IF(E27<>"",SUMIFS('Input data - Other'!$F:$F,'Input data - Other'!$B:$B,Crops!Z$6,'Input data - Other'!$D:$D,Crops!$E27),"") | AA27: =IF(F27<>"",SUMIFS('Input data - Other'!$F:$F,'Input data - Other'!$B:$B,Crops!AA$6,'Input data - Other'!$D:$D,Crops!$E27),"")
B28: DMD | C28: AFOCRPGRHVEGWTRE0 | D28: Afolu Crops Greenhouse Vegetables Existing 0 | E28: Greenhouse | F28: Vegetables | G28: Mton | H28: kha | I28: Annual | K28: =IF(Y18=0,"\I:",C28) -> AFOCRPGRHVEGWTRE0 | L28: Afolu Crops Greenhouse Vegetables Existing 0 | M28: WTRAFO | N28: AFOCRPVEGDEM | P28: =IF(IFERROR(VLOOKUP($K28,'Calc - Crops'!$L$24:$Y$47,8,FALSE)," ")=0," ",IFERROR(VLOOKUP($K28,'Calc - Crops'!$L$24:$Y$47,8,FALSE)/1000," ")) -> 0.014237984 | Q28: =IF(IFERROR(P28/(IFERROR(VLOOKUP(F28,'Calc - water'!$B$39:$G$48,6,FALSE),"")*IFERROR(VLOOKUP(E28,DefaultAFOLU!$C$32:$G$39,5,FALSE),"")),"")=0," ",IFERROR(P28/(IFERROR(VLOOKUP(F28,'Calc - water'!$B$39:$G$48,6,FALSE),"")*IFERROR(VLOOKUP(E28,DefaultAFOLU!$C$32:$G$39,5,FALSE),"")),"")) -> 0.022612715 | R28: 1 | S28: 4 | T28: =IF(Y28=0,Intro!$B$16+1,"") -> 2023 | V28: =IF(IFERROR(VLOOKUP($K28,'Calc - Crops'!$L$24:$Y$47,11,FALSE)," ")=0," ",IFERROR(VLOOKUP($K28,'Calc - Crops'!$L$24:$Y$47,11,FALSE)/$P28," ")) -> 573.68036 | W28: =IF(IFERROR(VLOOKUP($K28,'Calc - Crops'!$L$24:$Y$47,10,FALSE)," ")=0," ",IFERROR(VLOOKUP($K28,'Calc - Crops'!$L$24:$Y$47,10,FALSE)/$P28," ")) -> 0.029367284 | X28: =IF(IFERROR(VLOOKUP($K28,'Calc - Crops'!$L$24:$Y$47,9,FALSE)," ")=0," ",IFERROR(VLOOKUP($K28,'Calc - Crops'!$L$24:$Y$47,9,FALSE)/$P28," ")) -> 0.8006188 | Y28: =IFERROR(VLOOKUP($C28,'Calc - Crops'!$L$24:$Y$47,2,FALSE)/1000, " ") -> 0 | Z28: =IF(E28<>"",SUMIFS('Input data - Other'!$F:$F,'Input data - Other'!$B:$B,Crops!Z$6,'Input data - Other'!$D:$D,Crops!$E28),"") -> 0.156 | AA28: =IF(F28<>"",SUMIFS('Input data - Other'!$F:$F,'Input data - Other'!$B:$B,Crops!AA$6,'Input data - Other'!$D:$D,Crops!$E28),"") -> 1000
B29: \I: | K29: =IF(Y18=0,"\I:"," ") | O29: VEGWSB | P29: =IF(IFERROR(VLOOKUP($K29,'Calc - Crops'!$L$24:$Y$47,8,FALSE)," ")=0," ",IFERROR(VLOOKUP($K29,'Calc - Crops'!$L$24:$Y$47,8,FALSE)/1000," ")) | Q29: =IF(IFERROR(P29/(IFERROR(VLOOKUP(F29,'Calc - water'!$B$39:$G$48,6,FALSE),"")*IFERROR(VLOOKUP(E29,DefaultAFOLU!$C$32:$G$39,5,FALSE),"")),"")=0," ",IFERROR(P29/(IFERROR(VLOOKUP(F29,'Calc - water'!$B$39:$G$48,6,FALSE),"")*IFERROR(VLOOKUP(E29,DefaultAFOLU!$C$32:$G$39,5,FALSE),"")),"")) | T29: =IF(Y29=0,Intro!$B$16+1,"") | U29: =IFERROR(VLOOKUP(O29,DefaultAFOLU!$D$42:$G$50,4,TRUE)," ") -> 0.1 | V29: =IF(IFERROR(VLOOKUP($K29,'Calc - Crops'!$L$24:$Y$47,11,FALSE)," ")=0," ",IFERROR(VLOOKUP($K29,'Calc - Crops'!$L$24:$Y$47,11,FALSE)/$P29," ")) | W29: =IF(IFERROR(VLOOKUP($K29,'Calc - Crops'!$L$24:$Y$47,10,FALSE)," ")=0," ",IFERROR(VLOOKUP($K29,'Calc - Crops'!$L$24:$Y$47,10,FALSE)/$P29," ")) | X29: =IF(IFERROR(VLOOKUP($K29,'Calc - Crops'!$L$24:$Y$47,9,FALSE)," ")=0," ",IFERROR(VLOOKUP($K29,'Calc - Crops'!$L$24:$Y$47,9,FALSE)/$P29," ")) | Y29: =IFERROR(VLOOKUP($C29,'Calc - Crops'!$L$24:$Y$47,2,FALSE)/1000, " ") | Z29: =IF(E29<>"",SUMIFS('Input data - Other'!$F:$F,'Input data - Other'!$B:$B,Crops!Z$6,'Input data - Other'!$D:$D,Crops!$E29),"") | AA29: =IF(F29<>"",SUMIFS('Input data - Other'!$F:$F,'Input data - Other'!$B:$B,Crops!AA$6,'Input data - Other'!$D:$D,Crops!$E29),"")
B30: DMD | C30: AFOCRPGRHWCRWTRE0 | D30: Afolu Crops Greenhouse Woody crops Existing 0 | E30: Greenhouse | F30: Woody crops | G30: Mton | H30: kha | I30: Annual | K30: =IF(Y20=0,"\I:",C30) -> AFOCRPGRHWCRWTRE0 | L30: Afolu Crops Greenhouse Woody crops Existing 0 | M30: WTRAFO | N30: AFOCRPWCRDEM | P30: =IF(IFERROR(VLOOKUP($K30,'Calc - Crops'!$L$24:$Y$47,8,FALSE)," ")=0," ",IFERROR(VLOOKUP($K30,'Calc - Crops'!$L$24:$Y$47,8,FALSE)/1000," ")) -> 0.0045654966 | Q30: =IF(IFERROR(P30/(IFERROR(VLOOKUP(F30,'Calc - water'!$B$39:$G$48,6,FALSE),"")*IFERROR(VLOOKUP(E30,DefaultAFOLU!$C$32:$G$39,5,FALSE),"")),"")=0," ",IFERROR(P30/(IFERROR(VLOOKUP(F30,'Calc - water'!$B$39:$G$48,6,FALSE),"")*IFERROR(VLOOKUP(E30,DefaultAFOLU!$C$32:$G$39,5,FALSE),"")),"")) -> 60.873287 | R30: 1 | S30: 4 | T30: =IF(Y30=0,Intro!$B$16+1,"") -> 2023 | V30: =IF(IFERROR(VLOOKUP($K30,'Calc - Crops'!$L$24:$Y$47,11,FALSE)," ")=0," ",IFERROR(VLOOKUP($K30,'Calc - Crops'!$L$24:$Y$47,11,FALSE)/$P30," ")) -> 1789.0829 | W30: =IF(IFERROR(VLOOKUP($K30,'Calc - Crops'!$L$24:$Y$47,10,FALSE)," ")=0," ",IFERROR(VLOOKUP($K30,'Calc - Crops'!$L$24:$Y$47,10,FALSE)/$P30," ")) -> 0.091584981 | X30: =IF(IFERROR(VLOOKUP($K30,'Calc - Crops'!$L$24:$Y$47,9,FALSE)," ")=0," ",IFERROR(VLOOKUP($K30,'Calc - Crops'!$L$24:$Y$47,9,FALSE)/$P30," ")) -> 2.4968144 | Y30: =IFERROR(VLOOKUP($C30,'Calc - Crops'!$L$24:$Y$47,2,FALSE)/1000, " ") -> 0 | Z30: =IF(E30<>"",SUMIFS('Input data - Other'!$F:$F,'Input data - Other'!$B:$B,Crops!Z$6,'Input data - Other'!$D:$D,Crops!$E30),"") -> 0.156 | AA30: =IF(F30<>"",SUMIFS('Input data - Other'!$F:$F,'Input data - Other'!$B:$B,Crops!AA$6,'Input data - Other'!$D:$D,Crops!$E30),"") -> 1000
B31: \I: | K31: =IF(Y20=0,"\I:"," ") | O31: WCRWOC | P31: =IF(IFERROR(VLOOKUP($K31,'Calc - Crops'!$L$24:$Y$47,8,FALSE)," ")=0," ",IFERROR(VLOOKUP($K31,'Calc - Crops'!$L$24:$Y$47,8,FALSE)/1000," ")) | Q31: =IF(IFERROR(P31/(IFERROR(VLOOKUP(F31,'Calc - water'!$B$39:$G$48,6,FALSE),"")*IFERROR(VLOOKUP(E31,DefaultAFOLU!$C$32:$G$39,5,FALSE),"")),"")=0," ",IFERROR(P31/(IFERROR(VLOOKUP(F31,'Calc - water'!$B$39:$G$48,6,FALSE),"")*IFERROR(VLOOKUP(E31,DefaultAFOLU!$C$32:$G$39,5,FALSE),"")),"")) | T31: =IF(Y31=0,Intro!$B$16+1,"") | U31: =IFERROR(VLOOKUP(O31,DefaultAFOLU!$D$42:$G$50,4,TRUE)," ") -> 0.1 | V31: =IF(IFERROR(VLOOKUP($K31,'Calc - Crops'!$L$24:$Y$47,11,FALSE)," ")=0," ",IFERROR(VLOOKUP($K31,'Calc - Crops'!$L$24:$Y$47,11,FALSE)/$P31," ")) | W31: =IF(IFERROR(VLOOKUP($K31,'Calc - Crops'!$L$24:$Y$47,10,FALSE)," ")=0," ",IFERROR(VLOOKUP($K31,'Calc - Crops'!$L$24:$Y$47,10,FALSE)/$P31," ")) | X31: =IF(IFERROR(VLOOKUP($K31,'Calc - Crops'!$L$24:$Y$47,9,FALSE)," ")=0," ",IFERROR(VLOOKUP($K31,'Calc - Crops'!$L$24:$Y$47,9,FALSE)/$P31," ")) | Y31: =IFERROR(VLOOKUP($C31,'Calc - Crops'!$L$24:$Y$47,2,FALSE)/1000, " ") | Z31: =IF(E31<>"",SUMIFS('Input data - Other'!$F:$F,'Input data - Other'!$B:$B,Crops!Z$6,'Input data - Other'!$D:$D,Crops!$E31),"") | AA31: =IF(F31<>"",SUMIFS('Input data - Other'!$F:$F,'Input data - Other'!$B:$B,Crops!AA$6,'Input data - Other'!$D:$D,Crops!$E31),"")
B32: DMD | C32: AFOCRPGRHHAGWTRE0 | D32: Afolu Crops Greenhouse Herbs and greens Existing 0 | E32: Greenhouse | F32: Herbs and greens | G32: Mton | H32: kha | I32: Annual | K32: =IF(Y24=0,"\I:",C32) -> AFOCRPGRHHAGWTRE0 | L32: Afolu Crops Greenhouse Herbs and greens Existing 0 | M32: WTRAFO | N32: AFOCRPHAGDEM | P32: =IF(IFERROR(VLOOKUP($K32,'Calc - Crops'!$L$24:$Y$47,8,FALSE)," ")=0," ",IFERROR(VLOOKUP($K32,'Calc - Crops'!$L$24:$Y$47,8,FALSE)/1000," ")) -> 0.0043481333 | Q32: =IF(IFERROR(P32/(IFERROR(VLOOKUP(F32,'Calc - water'!$B$39:$G$48,6,FALSE),"")*IFERROR(VLOOKUP(E32,DefaultAFOLU!$C$32:$G$39,5,FALSE),"")),"")=0," ",IFERROR(P32/(IFERROR(VLOOKUP(F32,'Calc - water'!$B$39:$G$48,6,FALSE),"")*IFERROR(VLOOKUP(E32,DefaultAFOLU!$C$32:$G$39,5,FALSE),"")),"")) -> 57.975111 | R32: 1 | S32: 4 | T32: =IF(Y32=0,Intro!$B$16+1,"") -> 2023 | V32: =IF(IFERROR(VLOOKUP($K32,'Calc - Crops'!$L$24:$Y$47,11,FALSE)," ")=0," ",IFERROR(VLOOKUP($K32,'Calc - Crops'!$L$24:$Y$47,11,FALSE)/$P32," ")) -> 1878.5191 | W32: =IF(IFERROR(VLOOKUP($K32,'Calc - Crops'!$L$24:$Y$47,10,FALSE)," ")=0," ",IFERROR(VLOOKUP($K32,'Calc - Crops'!$L$24:$Y$47,10,FALSE)/$P32," ")) -> 0.096163315 | X32: =IF(IFERROR(VLOOKUP($K32,'Calc - Crops'!$L$24:$Y$47,9,FALSE)," ")=0," ",IFERROR(VLOOKUP($K32,'Calc - Crops'!$L$24:$Y$47,9,FALSE)/$P32," ")) -> 2.6216302 | Y32: =IFERROR(VLOOKUP($C32,'Calc - Crops'!$L$24:$Y$47,2,FALSE)/1000, " ") -> 0 | Z32: =IF(E32<>"",SUMIFS('Input data - Other'!$F:$F,'Input data - Other'!$B:$B,Crops!Z$6,'Input data - Other'!$D:$D,Crops!$E32),"") -> 0.156 | AA32: =IF(F32<>"",SUMIFS('Input data - Other'!$F:$F,'Input data - Other'!$B:$B,Crops!AA$6,'Input data - Other'!$D:$D,Crops!$E32),"") -> 1000
B33: \I: | K33: =IF(Y25=0,"\I:"," ") | O33: HAGWSB | P33: =IF(IFERROR(VLOOKUP($K33,'Calc - Crops'!$L$24:$Y$47,8,FALSE)," ")=0," ",IFERROR(VLOOKUP($K33,'Calc - Crops'!$L$24:$Y$47,8,FALSE)/1000," ")) | Q33: =IF(IFERROR(P33/(IFERROR(VLOOKUP(F33,'Calc - water'!$B$39:$G$48,6,FALSE),"")*IFERROR(VLOOKUP(E33,DefaultAFOLU!$C$32:$G$39,5,FALSE),"")),"")=0," ",IFERROR(P33/(IFERROR(VLOOKUP(F33,'Calc - water'!$B$39:$G$48,6,FALSE),"")*IFERROR(VLOOKUP(E33,DefaultAFOLU!$C$32:$G$39,5,FALSE),"")),"")) | T33: =IF(Y33=0,Intro!$B$16+1,"") | U33: =IFERROR(VLOOKUP(O33,DefaultAFOLU!$D$42:$G$50,4,TRUE)," ") -> 0.3 | V33: =IF(IFERROR(VLOOKUP($K33,'Calc - Crops'!$L$24:$Y$47,11,FALSE)," ")=0," ",IFERROR(VLOOKUP($K33,'Calc - Crops'!$L$24:$Y$47,11,FALSE)/$P33," ")) | W33: =IF(IFERROR(VLOOKUP($K33,'Calc - Crops'!$L$24:$Y$47,10,FALSE)," ")=0," ",IFERROR(VLOOKUP($K33,'Calc - Crops'!$L$24:$Y$47,10,FALSE)/$P33," ")) | X33: =IF(IFERROR(VLOOKUP($K33,'Calc - Crops'!$L$24:$Y$47,9,FALSE)," ")=0," ",IFERROR(VLOOKUP($K33,'Calc - Crops'!$L$24:$Y$47,9,FALSE)/$P33," ")) | Y33: =IFERROR(VLOOKUP($C33,'Calc - Crops'!$L$24:$Y$47,2,FALSE)/1000, " ") | Z33: =IF(E33<>"",SUMIFS('Input data - Other'!$F:$F,'Input data - Other'!$B:$B,Crops!Z$6,'Input data - Other'!$D:$D,Crops!$E33),"") | AA33: =IF(F33<>"",SUMIFS('Input data - Other'!$F:$F,'Input data - Other'!$B:$B,Crops!AA$6,'Input data - Other'!$D:$D,Crops!$E33),"")
B34: DMD | C34: AFOCRPAQPVEGWTRE0 | D34: Afolu Crops Aquaponics Vegetables Existing 0 | E34: Aquaponics | F34: Vegetables | G34: Mton | H34: kha | I34: Annual | K34: =IF(Y18=0,"\I:",C34) -> AFOCRPAQPVEGWTRE0 | L34: Afolu Crops Aquaponics Vegetables Existing 0 | M34: WTRAFO | N34: AFOCRPVEGDEM | P34: =IF(IFERROR(VLOOKUP($K34,'Calc - Crops'!$L$24:$Y$47,8,FALSE)," ")=0," ",IFERROR(VLOOKUP($K34,'Calc - Crops'!$L$24:$Y$47,8,FALSE)/1000," ")) -> 0.028475967 | Q34: =IF(IFERROR(P34/(IFERROR(VLOOKUP(F34,'Calc - water'!$B$39:$G$48,6,FALSE),"")*IFERROR(VLOOKUP(E34,DefaultAFOLU!$C$32:$G$39,5,FALSE),"")),"")=0," ",IFERROR(P34/(IFERROR(VLOOKUP(F34,'Calc - water'!$B$39:$G$48,6,FALSE),"")*IFERROR(VLOOKUP(E34,DefaultAFOLU!$C$32:$G$39,5,FALSE),"")),"")) -> 0.067838146 | R34: 1 | S34: 4 | T34: =IF(Y34=0,Intro!$B$16+1,"") -> 2023 | V34: =IF(IFERROR(VLOOKUP($K34,'Calc - Crops'!$L$24:$Y$47,11,FALSE)," ")=0," ",IFERROR(VLOOKUP($K34,'Calc - Crops'!$L$24:$Y$47,11,FALSE)/$P34," ")) -> 286.84018 | W34: =IF(IFERROR(VLOOKUP($K34,'Calc - Crops'!$L$24:$Y$47,10,FALSE)," ")=0," ",IFERROR(VLOOKUP($K34,'Calc - Crops'!$L$24:$Y$47,10,FALSE)/$P34," ")) -> 0.014683642 | X34: =IF(IFERROR(VLOOKUP($K34,'Calc - Crops'!$L$24:$Y$47,9,FALSE)," ")=0," ",IFERROR(VLOOKUP($K34,'Calc - Crops'!$L$24:$Y$47,9,FALSE)/$P34," ")) -> 0.4003094 | Y34: =IFERROR(VLOOKUP($C34,'Calc - Crops'!$L$24:$Y$47,2,FALSE)/1000, " ") -> 0 | Z34: =IF(E34<>"",SUMIFS('Input data - Other'!$F:$F,'Input data - Other'!$B:$B,Crops!Z$6,'Input data - Other'!$D:$D,Crops!$E34),"") -> 0.156 | AA34: =IF(F34<>"",SUMIFS('Input data - Other'!$F:$F,'Input data - Other'!$B:$B,Crops!AA$6,'Input data - Other'!$D:$D,Crops!$E34),"") -> 1500
B35: \I: | K35: =IF(Y18=0,"\I:"," ") | O35: VEGWSB | P35: =IF(IFERROR(VLOOKUP($K35,'Calc - Crops'!$L$24:$Y$47,8,FALSE)," ")=0," ",IFERROR(VLOOKUP($K35,'Calc - Crops'!$L$24:$Y$47,8,FALSE)/1000," ")) | Q35: =IF(IFERROR(P35/(IFERROR(VLOOKUP(F35,'Calc - water'!$B$39:$G$48,6,FALSE),"")*IFERROR(VLOOKUP(E35,DefaultAFOLU!$C$32:$G$39,5,FALSE),"")),"")=0," ",IFERROR(P35/(IFERROR(VLOOKUP(F35,'Calc - water'!$B$39:$G$48,6,FALSE),"")*IFERROR(VLOOKUP(E35,DefaultAFOLU!$C$32:$G$39,5,FALSE),"")),"")) | T35: =IF(Y35=0,Intro!$B$16+1,"") | U35: =IFERROR(VLOOKUP(O35,DefaultAFOLU!$D$42:$G$50,4,TRUE)," ") -> 0.1 | V35: =IF(IFERROR(VLOOKUP($K35,'Calc - Crops'!$L$24:$Y$47,11,FALSE)," ")=0," ",IFERROR(VLOOKUP($K35,'Calc - Crops'!$L$24:$Y$47,11,FALSE)/$P35," ")) | W35: =IF(IFERROR(VLOOKUP($K35,'Calc - Crops'!$L$24:$Y$47,10,FALSE)," ")=0," ",IFERROR(VLOOKUP($K35,'Calc - Crops'!$L$24:$Y$47,10,FALSE)/$P35," ")) | X35: =IF(IFERROR(VLOOKUP($K35,'Calc - Crops'!$L$24:$Y$47,9,FALSE)," ")=0," ",IFERROR(VLOOKUP($K35,'Calc - Crops'!$L$24:$Y$47,9,FALSE)/$P35," ")) | Y35: =IFERROR(VLOOKUP($C35,'Calc - Crops'!$L$24:$Y$47,2,FALSE)/1000, " ") | Z35: =IF(E35<>"",SUMIFS('Input data - Other'!$F:$F,'Input data - Other'!$B:$B,Crops!Z$6,'Input data - Other'!$D:$D,Crops!$E35),"") | AA35: =IF(F35<>"",SUMIFS('Input data - Other'!$F:$F,'Input data - Other'!$B:$B,Crops!AA$6,'Input data - Other'!$D:$D,Crops!$E35),"")
B36: DMD | C36: AFOCRPAQPHAGWTRE0 | D36: Afolu Crops Aquaponics Herbs and greens Existing 0 | E36: Aquaponics | F36: Herbs and greens | G36: Mton | H36: kha | I36: Annual | K36: =IF(Y24=0,"\I:",C36) -> AFOCRPAQPHAGWTRE0 | L36: Afolu Crops Aquaponics Herbs and greens Existing 0 | M36: WTRAFO | N36: AFOCRPHAGDEM | P36: =IF(IFERROR(VLOOKUP($K36,'Calc - Crops'!$L$24:$Y$47,8,FALSE)," ")=0," ",IFERROR(VLOOKUP($K36,'Calc - Crops'!$L$24:$Y$47,8,FALSE)/1000," ")) -> 0.0086962666 | Q36: =IF(IFERROR(P36/(IFERROR(VLOOKUP(F36,'Calc - water'!$B$39:$G$48,6,FALSE),"")*IFERROR(VLOOKUP(E36,DefaultAFOLU!$C$32:$G$39,5,FALSE),"")),"")=0," ",IFERROR(P36/(IFERROR(VLOOKUP(F36,'Calc - water'!$B$39:$G$48,6,FALSE),"")*IFERROR(VLOOKUP(E36,DefaultAFOLU!$C$32:$G$39,5,FALSE),"")),"")) -> 173.92533 | R36: 1 | S36: 4 | T36: =IF(Y36=0,Intro!$B$16+1,"") -> 2023 | V36: =IF(IFERROR(VLOOKUP($K36,'Calc - Crops'!$L$24:$Y$47,11,FALSE)," ")=0," ",IFERROR(VLOOKUP($K36,'Calc - Crops'!$L$24:$Y$47,11,FALSE)/$P36," ")) -> 939.25957 | W36: =IF(IFERROR(VLOOKUP($K36,'Calc - Crops'!$L$24:$Y$47,10,FALSE)," ")=0," ",IFERROR(VLOOKUP($K36,'Calc - Crops'!$L$24:$Y$47,10,FALSE)/$P36," ")) -> 0.048081658 | X36: =IF(IFERROR(VLOOKUP($K36,'Calc - Crops'!$L$24:$Y$47,9,FALSE)," ")=0," ",IFERROR(VLOOKUP($K36,'Calc - Crops'!$L$24:$Y$47,9,FALSE)/$P36," ")) -> 1.3108151 | Y36: =IFERROR(VLOOKUP($C36,'Calc - Crops'!$L$24:$Y$47,2,FALSE)/1000, " ") -> 0 | Z36: =IF(E36<>"",SUMIFS('Input data - Other'!$F:$F,'Input data - Other'!$B:$B,Crops!Z$6,'Input data - Other'!$D:$D,Crops!$E36),"") -> 0.156 | AA36: =IF(F36<>"",SUMIFS('Input data - Other'!$F:$F,'Input data - Other'!$B:$B,Crops!AA$6,'Input data - Other'!$D:$D,Crops!$E36),"") -> 1500
B37: \I: | K37: =IF(Y24=0,"\I:"," ") | O37: HAGWSB | P37: =IF(IFERROR(VLOOKUP($K37,'Calc - Crops'!$L$24:$Y$47,8,FALSE)," ")=0," ",IFERROR(VLOOKUP($K37,'Calc - Crops'!$L$24:$Y$47,8,FALSE)/1000," ")) | Q37: =IF(IFERROR(P37/(IFERROR(VLOOKUP(F37,'Calc - water'!$B$39:$G$48,6,FALSE),"")*IFERROR(VLOOKUP(E37,DefaultAFOLU!$C$32:$G$39,5,FALSE),"")),"")=0," ",IFERROR(P37/(IFERROR(VLOOKUP(F37,'Calc - water'!$B$39:$G$48,6,FALSE),"")*IFERROR(VLOOKUP(E37,DefaultAFOLU!$C$32:$G$39,5,FALSE),"")),"")) | T37: =IF(Y37=0,Intro!$B$16+1,"") | U37: =IFERROR(VLOOKUP(O37,DefaultAFOLU!$D$42:$G$50,4,TRUE)," ") -> 0.3 | V37: =IF(IFERROR(VLOOKUP($K37,'Calc - Crops'!$L$24:$Y$47,11,FALSE)," ")=0," ",IFERROR(VLOOKUP($K37,'Calc - Crops'!$L$24:$Y$47,11,FALSE)/$P37," ")) | W37: =IF(IFERROR(VLOOKUP($K37,'Calc - Crops'!$L$24:$Y$47,10,FALSE)," ")=0," ",IFERROR(VLOOKUP($K37,'Calc - Crops'!$L$24:$Y$47,10,FALSE)/$P37," ")) | X37: =IF(IFERROR(VLOOKUP($K37,'Calc - Crops'!$L$24:$Y$47,9,FALSE)," ")=0," ",IFERROR(VLOOKUP($K37,'Calc - Crops'!$L$24:$Y$47,9,FALSE)/$P37," ")) | Y37: =IFERROR(VLOOKUP($C37,'Calc - Crops'!$L$24:$Y$47,2,FALSE)/1000, " ") | Z37: =IF(E37<>"",SUMIFS('Input data - Other'!$F:$F,'Input data - Other'!$B:$B,Crops!Z$6,'Input data - Other'!$D:$D,Crops!$E37),"") | AA37: =IF(F37<>"",SUMIFS('Input data - Other'!$F:$F,'Input data - Other'!$B:$B,Crops!AA$6,'Input data - Other'!$D:$D,Crops!$E37),"")
B38: =IF(Y8=0,"\I:","DMD") -> DMD | C38: AFOCRPOFOCERWTRE0 | D38: Afolu Crops Organic Cereals Existing 0 | E38: Organic | F38: Cereals | G38: Mton | H38: kha | I38: Annual | K38: =IF(Y8=0,"\I:",C38) -> AFOCRPOFOCERWTRE0 | L38: Afolu Crops Organic Cereals Existing 0 | M38: WTRAFO | N38: AFOCRPCERDEM | P38: =IF(IFERROR(VLOOKUP($K38,'Calc - Crops'!$L$24:$Y$47,8,FALSE)," ")=0," ",IFERROR(VLOOKUP($K38,'Calc - Crops'!$L$24:$Y$47,8,FALSE)/1000," ")) -> 0.0004580524 | Q38: =IF(IFERROR(P38/(IFERROR(VLOOKUP(F38,'Calc - water'!$B$39:$G$48,6,FALSE),"")*IFERROR(VLOOKUP(E38,DefaultAFOLU!$C$32:$G$39,5,FALSE),"")),"")=0," ",IFERROR(P38/(IFERROR(VLOOKUP(F38,'Calc - water'!$B$39:$G$48,6,FALSE),"")*IFERROR(VLOOKUP(E38,DefaultAFOLU!$C$32:$G$39,5,FALSE),"")),"")) -> 4.580524 | R38: 1 | S38: 4 | T38: =IF(Y38=0,Intro!$B$16+1,"") -> 2023 | V38: =IF(IFERROR(VLOOKUP($K38,'Calc - Crops'!$L$24:$Y$47,11,FALSE)," ")=0," ",IFERROR(VLOOKUP($K38,'Calc - Crops'!$L$24:$Y$47,11,FALSE)/$P38," ")) -> 17832.134 | W38: =IF(IFERROR(VLOOKUP($K38,'Calc - Crops'!$L$24:$Y$47,10,FALSE)," ")=0," ",IFERROR(VLOOKUP($K38,'Calc - Crops'!$L$24:$Y$47,10,FALSE)/$P38," ")) -> 0.91284515 | X38: =IF(IFERROR(VLOOKUP($K38,'Calc - Crops'!$L$24:$Y$47,9,FALSE)," ")=0," ",IFERROR(VLOOKUP($K38,'Calc - Crops'!$L$24:$Y$47,9,FALSE)/$P38," ")) -> 17.90359 | Y38: =IFERROR(VLOOKUP($C38,'Calc - Crops'!$L$24:$Y$47,2,FALSE)/1000, " ") -> 0 | Z38: =IF(E38<>"",SUMIFS('Input data - Other'!$F:$F,'Input data - Other'!$B:$B,Crops!Z$6,'Input data - Other'!$D:$D,Crops!$E38),"") -> 0.156 | AA38: =IF(F38<>"",SUMIFS('Input data - Other'!$F:$F,'Input data - Other'!$B:$B,Crops!AA$6,'Input data - Other'!$D:$D,Crops!$E38),"") -> 0
